<?xml version="1.0" ?>
<!-- =================================================================================== -->
<!-- |    This document was autogenerated by xacro from /root/catkin_ws/src/abb_irbt6004_670_moveit_config/urdf/abb_irb6700_175_305_ibois.xacro | -->
<!-- |    EDITING THIS FILE BY HAND IS NOT RECOMMENDED                                 | -->
<!-- =================================================================================== -->
<robot name="big_robot">
    <link name="world" />
    <joint name="world_joint" type="fixed">
        <parent link="world" />
        <child link="rob1_axis" />
        <!--<origin xyz="0 0.0 0.0" rpy="0.0 0.0 3.14159265358979323846" />-->
        <origin rpy="0.0006690539774448019 0.000669029972214783 0.00003588000859488913" xyz="0 0.0 0.0" />
        <!--Update for the base frame of the track -->
    </joint>
    <!-- Conversion were obtained from http://www.e-paint.co.uk/Lab_values.asp
       unless otherwise stated. -->
    <link name="rob1_axis">
        <inertial>
            <mass value="120" />
            <inertia ixx="-4.98000" ixy="-0.00000" ixz="2.70000" iyy="-5.95200" iyz="-0.00000" izz="0.82800" />
            <origin xyz="0 0 0" rpy="0 0 0" />
        </inertial>
        <visual>
            <origin xyz="3.35 0.0 0.0" />
            <geometry>
                <mesh filename="package://abb_irbt6004_670_moveit_config/meshes/abb_irbt6004_670/visual/axis.stl" />
            </geometry>
            <material name="">
                <color rgba="0.9254902 0.9254902 0.9058824 1" />
            </material>
        </visual>
        <collision>
            <origin xyz="3.35 0.0 0.0" />
            <geometry>
                <mesh filename="package://abb_irbt6004_670_moveit_config/meshes/abb_irbt6004_670/collision/axis.stl" />
            </geometry>
        </collision>
    </link>
    <joint name="rob1_linear_axis_joint" type="prismatic">
        <parent link="rob1_axis" />
        <child link="rob1_pedestal" />
        <origin rpy="0 0 0" xyz="0 0 0" />
        <!--track origin or translation from origin-->
        <axis xyz="1 0 0" />
        <limit effort="100000" lower="0" upper="6.700" velocity="2.618" />
        <!--track limits or length-->
        <dynamics damping="0.2" friction="0" />
    </joint>
    <link name="rob1_pedestal">
        <inertial>
            <origin xyz="0.0 0.0 0.0" rpy="0 0 0" />
            <mass value="120.00000" />
            <inertia ixx="-4.98000" ixy="-0.00000" ixz="2.70000" iyy="-5.95200" iyz="-0.00000" izz="0.82800" />
        </inertial>
        <visual>
            <geometry>
                <mesh filename="package://abb_irbt6004_670_moveit_config/meshes/abb_irbt6004_670/visual/pedestal_250.stl" />
            </geometry>
            <material name="">
                <color rgba="0.9254902 0.9254902 0.9058824 1" />
            </material>
        </visual>
        <collision>
            <geometry>
                <mesh filename="package://abb_irbt6004_670_moveit_config/meshes/abb_irbt6004_670/collision/pedestal_250.stl" />
            </geometry>
        </collision>
    </link>
    <joint name="rob1_abb_joint" type="fixed">
        <parent link="rob1_pedestal" />
        <child link="rob1_base_link" />
        <origin rpy="0 0 1.57079632679489661923 " xyz="0 0 0 " />
        <!--rotation of robot pedestal 3.14159265358979323846 1.57079632679489661923-->
        <dynamics damping="0.2" friction="0" />
    </joint>
    <!-- Conversion were obtained from http://www.e-paint.co.uk/Lab_values.asp
       unless otherwise stated. -->
    <!-- link list -->
    <link name="rob1_base_link">
        <visual>
            <origin rpy="0 0 0" xyz="0 0 0" />
            <geometry>
                <mesh filename="package://abb_irb6700_support/meshes/irb6700/visual/base_link.stl" />
            </geometry>
            <material name="">
                <color rgba="0.9254902 0.9254902 0.9058824 1" />
            </material>
        </visual>
        <collision>
            <origin rpy="0 0 0" xyz="0 0 0" />
            <geometry>
                <mesh filename="package://abb_irb6700_support/meshes/irb6700/collision/base_link.stl" />
            </geometry>
            <material name="">
                <color rgba="1 1 0 1" />
            </material>
        </collision>
        <inertial>
            <mass value="0.1" />
            <origin xyz="0 0 0" rpy="0 0 0" />
            <inertia ixx="0.03" iyy="0.03" izz="0.03" ixy="0.0" ixz="0.0" iyz="0.0" />
        </inertial>
    </link>
    <link name="rob1_link_1">
        <visual>
            <origin rpy="0 0 0" xyz="0 0 0" />
            <geometry>
                <mesh filename="package://abb_irb6700_support/meshes/irb6700/visual/link_1.stl" />
            </geometry>
            <material name="">
                <color rgba="0.9254902 0.9254902 0.9058824 1" />
            </material>
        </visual>
        <collision>
            <origin rpy="0 0 0" xyz="0 0 0" />
            <geometry>
                <mesh filename="package://abb_irb6700_support/meshes/irb6700/collision/link_1.stl" />
            </geometry>
            <material name="">
                <color rgba="1 1 0 1" />
            </material>
        </collision>
        <inertial>
            <mass value="0.1" />
            <origin xyz="0 0 0" rpy="0 0 0" />
            <inertia ixx="0.03" iyy="0.03" izz="0.03" ixy="0.0" ixz="0.0" iyz="0.0" />
        </inertial>
    </link>
    <link name="rob1_cylinder">
        <visual>
            <origin rpy="0 0 0" xyz="0 0 0" />
            <geometry>
                <mesh filename="package://abb_irb6700_support/meshes/irb6700/visual/cylinder.stl" />
            </geometry>
            <material name="">
                <color rgba="0.9254902 0.9254902 0.9058824 1" />
            </material>
        </visual>
        <collision>
            <origin rpy="0 0 0" xyz="0 0 0" />
            <geometry>
                <mesh filename="package://abb_irb6700_support/meshes/irb6700/collision/cylinder.stl" />
            </geometry>
            <material name="">
                <color rgba="1 1 0 1" />
            </material>
        </collision>
        <inertial>
            <mass value="0.1" />
            <origin xyz="0 0 0" rpy="0 0 0" />
            <inertia ixx="0.03" iyy="0.03" izz="0.03" ixy="0.0" ixz="0.0" iyz="0.0" />
        </inertial>
    </link>
    <link name="rob1_piston">
        <visual>
            <origin rpy="0 0 0" xyz="0 0 0" />
            <geometry>
                <mesh filename="package://abb_irb6700_support/meshes/irb6700/visual/piston.stl" />
            </geometry>
            <material name="">
                <color rgba="0.9254902 0.9254902 0.9058824 1" />
            </material>
        </visual>
        <collision>
            <origin rpy="0 0 0" xyz="0 0 0" />
            <geometry>
                <mesh filename="package://abb_irb6700_support/meshes/irb6700/collision/piston.stl" />
            </geometry>
            <material name="">
                <color rgba="1 1 0 1" />
            </material>
        </collision>
        <inertial>
            <mass value="0.1" />
            <origin xyz="0 0 0" rpy="0 0 0" />
            <inertia ixx="0.03" iyy="0.03" izz="0.03" ixy="0.0" ixz="0.0" iyz="0.0" />
        </inertial>
    </link>
    <link name="rob1_link_2">
        <visual>
            <origin rpy="0 0 0" xyz="0 0 0" />
            <geometry>
                <mesh filename="package://abb_irb6700_support/meshes/irb6700_175_305/visual/link_2.stl" />
            </geometry>
            <material name="">
                <color rgba="0.9254902 0.9254902 0.9058824 1" />
            </material>
        </visual>
        <collision>
            <origin rpy="0 0 0" xyz="0 0 0" />
            <geometry>
                <mesh filename="package://abb_irb6700_support/meshes/irb6700_175_305/collision/link_2.stl" />
            </geometry>
            <material name="">
                <color rgba="1 1 0 1" />
            </material>
        </collision>
        <inertial>
            <mass value="0.1" />
            <origin xyz="0 0 0" rpy="0 0 0" />
            <inertia ixx="0.03" iyy="0.03" izz="0.03" ixy="0.0" ixz="0.0" iyz="0.0" />
        </inertial>
    </link>
    <link name="rob1_link_3">
        <visual>
            <origin rpy="0 0 0" xyz="0 0 0" />
            <geometry>
                <mesh filename="package://abb_irb6700_support/meshes/irb6700_175_305/visual/link_3.stl" />
            </geometry>
            <material name="">
                <color rgba="0.9254902 0.9254902 0.9058824 1" />
            </material>
        </visual>
        <collision>
            <origin rpy="0 0 0" xyz="0 0 0" />
            <geometry>
                <mesh filename="package://abb_irb6700_support/meshes/irb6700_175_305/collision/link_3.stl" />
            </geometry>
            <material name="">
                <color rgba="1 1 0 1" />
            </material>
        </collision>
        <inertial>
            <mass value="0.1" />
            <origin xyz="0 0 0" rpy="0 0 0" />
            <inertia ixx="0.03" iyy="0.03" izz="0.03" ixy="0.0" ixz="0.0" iyz="0.0" />
        </inertial>
    </link>
    <link name="rob1_link_4">
        <visual>
            <origin rpy="0 0 0" xyz="0 0 0" />
            <geometry>
                <mesh filename="package://abb_irb6700_support/meshes/irb6700_175_305/visual/link_4.stl" />
            </geometry>
            <material name="">
                <color rgba="0.9254902 0.9254902 0.9058824 1" />
            </material>
        </visual>
        <collision>
            <origin rpy="0 0 0" xyz="0 0 0" />
            <geometry>
                <mesh filename="package://abb_irb6700_support/meshes/irb6700_175_305/collision/link_4.stl" />
            </geometry>
            <material name="">
                <color rgba="1 1 0 1" />
            </material>
        </collision>
        <inertial>
            <mass value="0.1" />
            <origin xyz="0 0 0" rpy="0 0 0" />
            <inertia ixx="0.03" iyy="0.03" izz="0.03" ixy="0.0" ixz="0.0" iyz="0.0" />
        </inertial>
    </link>
    <link name="rob1_link_5">
        <visual>
            <origin rpy="0 0 0" xyz="0 0 0" />
            <geometry>
                <mesh filename="package://abb_irb6700_support/meshes/irb6700/visual/link_5.stl" />
            </geometry>
            <material name="">
                <color rgba="0.9254902 0.9254902 0.9058824 1" />
            </material>
        </visual>
        <collision>
            <origin rpy="0 0 0" xyz="0 0 0" />
            <geometry>
                <mesh filename="package://abb_irb6700_support/meshes/irb6700/collision/link_5.stl" />
            </geometry>
            <material name="">
                <color rgba="1 1 0 1" />
            </material>
        </collision>
        <inertial>
            <mass value="0.1" />
            <origin xyz="0 0 0" rpy="0 0 0" />
            <inertia ixx="0.03" iyy="0.03" izz="0.03" ixy="0.0" ixz="0.0" iyz="0.0" />
        </inertial>
    </link>
    <link name="rob1_link_6">
        <visual>
            <origin rpy="0 0 0" xyz="0 0 0" />
            <geometry>
                <mesh filename="package://abb_irb6700_support/meshes/irb6700/visual/link_6.stl" />
            </geometry>
            <material name="">
                <color rgba="0.9254902 0.9254902 0.9058824 1" />
            </material>
        </visual>
        <collision>
            <origin rpy="0 0 0" xyz="0 0 0" />
            <geometry>
                <mesh filename="package://abb_irb6700_support/meshes/irb6700/collision/link_6.stl" />
            </geometry>
            <material name="">
                <color rgba="1 1 0 1" />
            </material>
        </collision>
        <inertial>
            <mass value="0.1" />
            <origin xyz="0 0 0" rpy="0 0 0" />
            <inertia ixx="0.03" iyy="0.03" izz="0.03" ixy="0.0" ixz="0.0" iyz="0.0" />
        </inertial>
    </link>
    <joint name="rob1_joint_1" type="revolute">
        <origin rpy="0 0 0" xyz="0 0 0.78" />
        <parent link="rob1_base_link" />
        <child link="rob1_link_1" />
        <axis xyz="0 0 1" />
        <limit effort="0" lower="-2.9670597283903604" upper="2.9670597283903604" velocity="1.9198621771937625" />
    </joint>
    <joint name="rob1_joint_2" type="revolute">
        <origin rpy="0 0 0" xyz="0.32 0 0" />
        <parent link="rob1_link_1" />
        <child link="rob1_link_2" />
        <axis xyz="0 1 0" />
        <limit effort="0" lower="-1.1344640137963142" upper="1.4835298641951802" velocity="1.9198621771937625" />
    </joint>
    <joint name="rob1_joint_3" type="revolute">
        <origin rpy="0 0 0" xyz="0 0 1.135" />
        <parent link="rob1_link_2" />
        <child link="rob1_link_3" />
        <axis xyz="0 1 0" />
        <limit effort="0" lower="-3.141592653589793" upper="1.2217304763960306" velocity="1.9198621771937625" />
    </joint>
    <joint name="rob1_joint_4" type="revolute">
        <origin rpy="0 0 0" xyz="0 0 0.2" />
        <parent link="rob1_link_3" />
        <child link="rob1_link_4" />
        <axis xyz="1 0 0" />
        <limit effort="0" lower="-5.235987755982989" upper="5.235987755982989" velocity="3.3161255787892263" />
    </joint>
    <joint name="rob1_joint_5" type="revolute">
        <origin rpy="0 0 0" xyz="1.593 0 0" />
        <parent link="rob1_link_4" />
        <child link="rob1_link_5" />
        <axis xyz="0 1 0" />
        <limit effort="0" lower="-2.2689280275926285" upper="2.2689280275926285" velocity="2.6179938779914944" />
    </joint>
    <joint name="rob1_joint_6" type="revolute">
        <origin rpy="0 0 0" xyz="0.2 0 0" />
        <parent link="rob1_link_5" />
        <child link="rob1_link_6" />
        <axis xyz="1 0 0" />
        <limit effort="0" lower="-6.283185307179586" upper="6.283185307179586" velocity="3.6651914291880923" />
    </joint>
    <joint name="rob1_cylinder_joint" type="revolute">
        <origin rpy="0 0 0" xyz="-0.349 -0.194 -0.142" />
        <parent link="rob1_link_1" />
        <child link="rob1_cylinder" />
        <axis xyz="0 1 0" />
        <mimic joint="rob1_joint_2" multiplier="-0.25" />
        <limit effort="0" lower="-0.28361600344907856" upper="0.37088246604879505" velocity="100" />
    </joint>
    <joint name="rob1_piston_joint" type="prismatic">
        <origin rpy="0.20897 0 -1.5707963267948966" xyz="0 0 0" />
        <parent link="rob1_cylinder" />
        <child link="rob1_piston" />
        <axis xyz="0 1 0" />
        <mimic joint="rob1_joint_2" multiplier="0.15" />
        <limit effort="0" lower="-0.25" upper="0.25" velocity="100" />
    </joint>
    <!-- ROS-Industrial 'base' frame: base_link to ABB World Coordinates transform -->
    <link name="rob1_base" />
    <joint name="rob1_base_link-base" type="fixed">
        <origin rpy="0 0 0" xyz="0 0 0" />
        <parent link="rob1_base_link" />
        <child link="rob1_base" />
    </joint>
    <!-- ROS-Industrial 'flange' frame: attachment point for EEF models -->
    <link name="rob1_flange" />
    <joint name="rob1_joint_6-flange" type="fixed">
        <origin rpy="0 0 0" xyz="0 0 0" />
        <parent link="rob1_link_6" />
        <child link="rob1_flange" />
    </joint>
    <!-- ROS-Industrial 'tool0' frame: all-zeros tool frame -->
    <link name="rob1_tool0" />
    <joint name="rob1_link_6-tool0" type="fixed">
        <origin rpy="0 1.5707963267948966 0" xyz="0 0 0" />
        <parent link="rob1_flange" />
        <child link="rob1_tool0" />
    </joint>
    <!--for multiple robots-->
    <transmission name="trans_rob1_linear_axis_joint">
        <type>transmission_interface/SimpleTransmission</type>
        <joint name="rob1_linear_axis_joint">
            <hardwareInterface>hardware_interface/EffortJointInterface</hardwareInterface>
        </joint>
        <actuator name="rob1_linear_axis_joint_motor">
            <hardwareInterface>hardware_interface/EffortJointInterface</hardwareInterface>
            <mechanicalReduction>1</mechanicalReduction>
        </actuator>
    </transmission>
    <transmission name="trans_rob1_joint_1">
        <type>transmission_interface/SimpleTransmission</type>
        <joint name="rob1_joint_1">
            <hardwareInterface>hardware_interface/EffortJointInterface</hardwareInterface>
        </joint>
        <actuator name="rob1_joint_1_motor">
            <hardwareInterface>hardware_interface/EffortJointInterface</hardwareInterface>
            <mechanicalReduction>1</mechanicalReduction>
        </actuator>
    </transmission>
    <transmission name="trans_rob1_joint_2">
        <type>transmission_interface/SimpleTransmission</type>
        <joint name="rob1_joint_2">
            <hardwareInterface>hardware_interface/EffortJointInterface</hardwareInterface>
        </joint>
        <actuator name="rob1_joint_2_motor">
            <hardwareInterface>hardware_interface/EffortJointInterface</hardwareInterface>
            <mechanicalReduction>1</mechanicalReduction>
        </actuator>
    </transmission>
    <transmission name="trans_rob1_joint_3">
        <type>transmission_interface/SimpleTransmission</type>
        <joint name="rob1_joint_3">
            <hardwareInterface>hardware_interface/EffortJointInterface</hardwareInterface>
        </joint>
        <actuator name="rob1_joint_3_motor">
            <hardwareInterface>hardware_interface/EffortJointInterface</hardwareInterface>
            <mechanicalReduction>1</mechanicalReduction>
        </actuator>
    </transmission>
    <transmission name="trans_rob1_joint_4">
        <type>transmission_interface/SimpleTransmission</type>
        <joint name="rob1_joint_4">
            <hardwareInterface>hardware_interface/EffortJointInterface</hardwareInterface>
        </joint>
        <actuator name="rob1_joint_4_motor">
            <hardwareInterface>hardware_interface/EffortJointInterface</hardwareInterface>
            <mechanicalReduction>1</mechanicalReduction>
        </actuator>
    </transmission>
    <transmission name="trans_rob1_joint_5">
        <type>transmission_interface/SimpleTransmission</type>
        <joint name="rob1_joint_5">
            <hardwareInterface>hardware_interface/EffortJointInterface</hardwareInterface>
        </joint>
        <actuator name="rob1_joint_5_motor">
            <hardwareInterface>hardware_interface/EffortJointInterface</hardwareInterface>
            <mechanicalReduction>1</mechanicalReduction>
        </actuator>
    </transmission>
    <transmission name="trans_rob1_joint_6">
        <type>transmission_interface/SimpleTransmission</type>
        <joint name="rob1_joint_6">
            <hardwareInterface>hardware_interface/EffortJointInterface</hardwareInterface>
        </joint>
        <actuator name="rob1_joint_6_motor">
            <hardwareInterface>hardware_interface/EffortJointInterface</hardwareInterface>
            <mechanicalReduction>1</mechanicalReduction>
        </actuator>
    </transmission>
    <transmission name="trans_rob1_cylinder_joint">
        <type>transmission_interface/SimpleTransmission</type>
        <joint name="rob1_cylinder_joint">
            <hardwareInterface>hardware_interface/EffortJointInterface</hardwareInterface>
        </joint>
        <actuator name="rob1_cylinder_joint_motor">
            <hardwareInterface>hardware_interface/EffortJointInterface</hardwareInterface>
            <mechanicalReduction>1</mechanicalReduction>
        </actuator>
    </transmission>
    <transmission name="trans_rob1_piston_joint">
        <type>transmission_interface/SimpleTransmission</type>
        <joint name="rob1_piston_joint">
            <hardwareInterface>hardware_interface/EffortJointInterface</hardwareInterface>
        </joint>
        <actuator name="rob1_piston_joint_motor">
            <hardwareInterface>hardware_interface/EffortJointInterface</hardwareInterface>
            <mechanicalReduction>1</mechanicalReduction>
        </actuator>
    </transmission>
    <gazebo>
        <plugin name="gazebo_ros_control">
            <robotNamespace>/</robotNamespace>
        </plugin>
    </gazebo>
</robot>

